INFO:     Will watch for changes in these directories: ['/home/admin_/final_demo/capi/demo-gen-capi/backend']
INFO:     Uvicorn running on http://0.0.0.0:8000 (Press CTRL+C to quit)
INFO:     Started reloader process [13979] using StatReload
Process SpawnProcess-1:
Traceback (most recent call last):
  File "/usr/lib/python3.12/multiprocessing/process.py", line 314, in _bootstrap
    self.run()
  File "/usr/lib/python3.12/multiprocessing/process.py", line 108, in run
    self._target(*self._args, **self._kwargs)
  File "/home/admin_/.local/lib/python3.12/site-packages/uvicorn/_subprocess.py", line 80, in subprocess_started
    target(sockets=sockets)
  File "/home/admin_/.local/lib/python3.12/site-packages/uvicorn/server.py", line 67, in run
    return asyncio_run(self.serve(sockets=sockets), loop_factory=self.config.get_loop_factory())
           ^^^^^^^^^^^^^^^^^^^^^^^^^^^^^^^^^^^^^^^^^^^^^^^^^^^^^^^^^^^^^^^^^^^^^^^^^^^^^^^^^^^^^
  File "/usr/lib/python3.12/asyncio/runners.py", line 194, in run
    return runner.run(main)
           ^^^^^^^^^^^^^^^^
  File "/usr/lib/python3.12/asyncio/runners.py", line 118, in run
    return self._loop.run_until_complete(task)
           ^^^^^^^^^^^^^^^^^^^^^^^^^^^^^^^^^^^
  File "/usr/lib/python3.12/asyncio/base_events.py", line 687, in run_until_complete
    return future.result()
           ^^^^^^^^^^^^^^^
  File "/home/admin_/.local/lib/python3.12/site-packages/uvicorn/server.py", line 71, in serve
    await self._serve(sockets)
  File "/home/admin_/.local/lib/python3.12/site-packages/uvicorn/server.py", line 78, in _serve
    config.load()
  File "/home/admin_/.local/lib/python3.12/site-packages/uvicorn/config.py", line 438, in load
    self.loaded_app = import_from_string(self.app)
                      ^^^^^^^^^^^^^^^^^^^^^^^^^^^^
  File "/home/admin_/.local/lib/python3.12/site-packages/uvicorn/importer.py", line 19, in import_from_string
    module = importlib.import_module(module_str)
             ^^^^^^^^^^^^^^^^^^^^^^^^^^^^^^^^^^^
  File "/usr/lib/python3.12/importlib/__init__.py", line 90, in import_module
    return _bootstrap._gcd_import(name[level:], package, level)
           ^^^^^^^^^^^^^^^^^^^^^^^^^^^^^^^^^^^^^^^^^^^^^^^^^^^^
  File "<frozen importlib._bootstrap>", line 1387, in _gcd_import
  File "<frozen importlib._bootstrap>", line 1360, in _find_and_load
  File "<frozen importlib._bootstrap>", line 1331, in _find_and_load_unlocked
  File "<frozen importlib._bootstrap>", line 935, in _load_unlocked
  File "<frozen importlib._bootstrap_external>", line 991, in exec_module
  File "<frozen importlib._bootstrap_external>", line 1129, in get_code
  File "<frozen importlib._bootstrap_external>", line 1059, in source_to_code
  File "<frozen importlib._bootstrap>", line 488, in _call_with_frames_removed
  File "/home/admin_/final_demo/capi/demo-gen-capi/backend/api.py", line 151
    , port=8000)
               ^
SyntaxError: unmatched ')'
WARNING:  StatReload detected changes in 'api.py'. Reloading...
INFO:     Started server process [14008]
INFO:     Waiting for application startup.
INFO:     Application startup complete.
ERROR:    Traceback (most recent call last):
  File "/usr/lib/python3.12/asyncio/runners.py", line 194, in run
    return runner.run(main)
           ^^^^^^^^^^^^^^^^
  File "/usr/lib/python3.12/asyncio/runners.py", line 118, in run
    return self._loop.run_until_complete(task)
           ^^^^^^^^^^^^^^^^^^^^^^^^^^^^^^^^^^^
  File "/usr/lib/python3.12/asyncio/base_events.py", line 687, in run_until_complete
    return future.result()
           ^^^^^^^^^^^^^^^
  File "/home/admin_/.local/lib/python3.12/site-packages/uvicorn/server.py", line 71, in serve
    await self._serve(sockets)
  File "/home/admin_/.local/lib/python3.12/site-packages/uvicorn/server.py", line 86, in _serve
    await self.startup(sockets=sockets)
  File "/home/admin_/.local/lib/python3.12/site-packages/uvicorn/server.py", line 136, in startup
    server = await loop.create_server(create_protocol, sock=sock, ssl=config.ssl, backlog=config.backlog)
             ^^^^^^^^^^^^^^^^^^^^^^^^^^^^^^^^^^^^^^^^^^^^^^^^^^^^^^^^^^^^^^^^^^^^^^^^^^^^^^^^^^^^^^^^^^^^
  File "/usr/lib/python3.12/asyncio/base_events.py", line 1597, in create_server
    server._start_serving()
  File "/usr/lib/python3.12/asyncio/base_events.py", line 317, in _start_serving
    sock.listen(self._backlog)
OSError: [Errno 98] Address already in use

During handling of the above exception, another exception occurred:

Traceback (most recent call last):
  File "/home/admin_/.local/lib/python3.12/site-packages/starlette/routing.py", line 701, in lifespan
    await receive()
  File "/home/admin_/.local/lib/python3.12/site-packages/uvicorn/lifespan/on.py", line 137, in receive
    return await self.receive_queue.get()
           ^^^^^^^^^^^^^^^^^^^^^^^^^^^^^^
  File "/usr/lib/python3.12/asyncio/queues.py", line 158, in get
    await getter
asyncio.exceptions.CancelledError

Process SpawnProcess-2:
Traceback (most recent call last):
  File "/usr/lib/python3.12/multiprocessing/process.py", line 314, in _bootstrap
    self.run()
  File "/usr/lib/python3.12/multiprocessing/process.py", line 108, in run
    self._target(*self._args, **self._kwargs)
  File "/home/admin_/.local/lib/python3.12/site-packages/uvicorn/_subprocess.py", line 80, in subprocess_started
    target(sockets=sockets)
  File "/home/admin_/.local/lib/python3.12/site-packages/uvicorn/server.py", line 67, in run
    return asyncio_run(self.serve(sockets=sockets), loop_factory=self.config.get_loop_factory())
           ^^^^^^^^^^^^^^^^^^^^^^^^^^^^^^^^^^^^^^^^^^^^^^^^^^^^^^^^^^^^^^^^^^^^^^^^^^^^^^^^^^^^^
  File "/usr/lib/python3.12/asyncio/runners.py", line 194, in run
    return runner.run(main)
           ^^^^^^^^^^^^^^^^
  File "/usr/lib/python3.12/asyncio/runners.py", line 118, in run
    return self._loop.run_until_complete(task)
           ^^^^^^^^^^^^^^^^^^^^^^^^^^^^^^^^^^^
  File "/usr/lib/python3.12/asyncio/base_events.py", line 687, in run_until_complete
    return future.result()
           ^^^^^^^^^^^^^^^
  File "/home/admin_/.local/lib/python3.12/site-packages/uvicorn/server.py", line 71, in serve
    await self._serve(sockets)
  File "/home/admin_/.local/lib/python3.12/site-packages/uvicorn/server.py", line 86, in _serve
    await self.startup(sockets=sockets)
  File "/home/admin_/.local/lib/python3.12/site-packages/uvicorn/server.py", line 136, in startup
    server = await loop.create_server(create_protocol, sock=sock, ssl=config.ssl, backlog=config.backlog)
             ^^^^^^^^^^^^^^^^^^^^^^^^^^^^^^^^^^^^^^^^^^^^^^^^^^^^^^^^^^^^^^^^^^^^^^^^^^^^^^^^^^^^^^^^^^^^
  File "/usr/lib/python3.12/asyncio/base_events.py", line 1597, in create_server
    server._start_serving()
  File "/usr/lib/python3.12/asyncio/base_events.py", line 317, in _start_serving
    sock.listen(self._backlog)
OSError: [Errno 98] Address already in use
Data agent 'klick_agent' already exists.
WARNING:  StatReload detected changes in 'api.py'. Reloading...
INFO:     Started server process [14214]
INFO:     Waiting for application startup.
INFO:     Application startup complete.
ERROR:    Traceback (most recent call last):
  File "/usr/lib/python3.12/asyncio/runners.py", line 194, in run
    return runner.run(main)
           ^^^^^^^^^^^^^^^^
  File "/usr/lib/python3.12/asyncio/runners.py", line 118, in run
    return self._loop.run_until_complete(task)
           ^^^^^^^^^^^^^^^^^^^^^^^^^^^^^^^^^^^
  File "/usr/lib/python3.12/asyncio/base_events.py", line 687, in run_until_complete
    return future.result()
           ^^^^^^^^^^^^^^^
  File "/home/admin_/.local/lib/python3.12/site-packages/uvicorn/server.py", line 71, in serve
    await self._serve(sockets)
  File "/home/admin_/.local/lib/python3.12/site-packages/uvicorn/server.py", line 86, in _serve
    await self.startup(sockets=sockets)
  File "/home/admin_/.local/lib/python3.12/site-packages/uvicorn/server.py", line 136, in startup
    server = await loop.create_server(create_protocol, sock=sock, ssl=config.ssl, backlog=config.backlog)
             ^^^^^^^^^^^^^^^^^^^^^^^^^^^^^^^^^^^^^^^^^^^^^^^^^^^^^^^^^^^^^^^^^^^^^^^^^^^^^^^^^^^^^^^^^^^^
  File "/usr/lib/python3.12/asyncio/base_events.py", line 1597, in create_server
    server._start_serving()
  File "/usr/lib/python3.12/asyncio/base_events.py", line 317, in _start_serving
    sock.listen(self._backlog)
OSError: [Errno 98] Address already in use

During handling of the above exception, another exception occurred:

Traceback (most recent call last):
  File "/home/admin_/.local/lib/python3.12/site-packages/starlette/routing.py", line 701, in lifespan
    await receive()
  File "/home/admin_/.local/lib/python3.12/site-packages/uvicorn/lifespan/on.py", line 137, in receive
    return await self.receive_queue.get()
           ^^^^^^^^^^^^^^^^^^^^^^^^^^^^^^
  File "/usr/lib/python3.12/asyncio/queues.py", line 158, in get
    await getter
asyncio.exceptions.CancelledError

Process SpawnProcess-3:
Traceback (most recent call last):
  File "/usr/lib/python3.12/multiprocessing/process.py", line 314, in _bootstrap
    self.run()
  File "/usr/lib/python3.12/multiprocessing/process.py", line 108, in run
    self._target(*self._args, **self._kwargs)
  File "/home/admin_/.local/lib/python3.12/site-packages/uvicorn/_subprocess.py", line 80, in subprocess_started
    target(sockets=sockets)
  File "/home/admin_/.local/lib/python3.12/site-packages/uvicorn/server.py", line 67, in run
    return asyncio_run(self.serve(sockets=sockets), loop_factory=self.config.get_loop_factory())
           ^^^^^^^^^^^^^^^^^^^^^^^^^^^^^^^^^^^^^^^^^^^^^^^^^^^^^^^^^^^^^^^^^^^^^^^^^^^^^^^^^^^^^
  File "/usr/lib/python3.12/asyncio/runners.py", line 194, in run
    return runner.run(main)
           ^^^^^^^^^^^^^^^^
  File "/usr/lib/python3.12/asyncio/runners.py", line 118, in run
    return self._loop.run_until_complete(task)
           ^^^^^^^^^^^^^^^^^^^^^^^^^^^^^^^^^^^
  File "/usr/lib/python3.12/asyncio/base_events.py", line 687, in run_until_complete
    return future.result()
           ^^^^^^^^^^^^^^^
  File "/home/admin_/.local/lib/python3.12/site-packages/uvicorn/server.py", line 71, in serve
    await self._serve(sockets)
  File "/home/admin_/.local/lib/python3.12/site-packages/uvicorn/server.py", line 86, in _serve
    await self.startup(sockets=sockets)
  File "/home/admin_/.local/lib/python3.12/site-packages/uvicorn/server.py", line 136, in startup
    server = await loop.create_server(create_protocol, sock=sock, ssl=config.ssl, backlog=config.backlog)
             ^^^^^^^^^^^^^^^^^^^^^^^^^^^^^^^^^^^^^^^^^^^^^^^^^^^^^^^^^^^^^^^^^^^^^^^^^^^^^^^^^^^^^^^^^^^^
  File "/usr/lib/python3.12/asyncio/base_events.py", line 1597, in create_server
    server._start_serving()
  File "/usr/lib/python3.12/asyncio/base_events.py", line 317, in _start_serving
    sock.listen(self._backlog)
OSError: [Errno 98] Address already in use
Data agent 'klick_agent' already exists.
WARNING:  StatReload detected changes in 'api.py'. Reloading...
Process SpawnProcess-4:
Traceback (most recent call last):
  File "/usr/lib/python3.12/multiprocessing/process.py", line 314, in _bootstrap
    self.run()
  File "/usr/lib/python3.12/multiprocessing/process.py", line 108, in run
    self._target(*self._args, **self._kwargs)
  File "/home/admin_/.local/lib/python3.12/site-packages/uvicorn/_subprocess.py", line 80, in subprocess_started
    target(sockets=sockets)
  File "/home/admin_/.local/lib/python3.12/site-packages/uvicorn/server.py", line 67, in run
    return asyncio_run(self.serve(sockets=sockets), loop_factory=self.config.get_loop_factory())
           ^^^^^^^^^^^^^^^^^^^^^^^^^^^^^^^^^^^^^^^^^^^^^^^^^^^^^^^^^^^^^^^^^^^^^^^^^^^^^^^^^^^^^
  File "/usr/lib/python3.12/asyncio/runners.py", line 194, in run
    return runner.run(main)
           ^^^^^^^^^^^^^^^^
  File "/usr/lib/python3.12/asyncio/runners.py", line 118, in run
    return self._loop.run_until_complete(task)
           ^^^^^^^^^^^^^^^^^^^^^^^^^^^^^^^^^^^
  File "/usr/lib/python3.12/asyncio/base_events.py", line 687, in run_until_complete
    return future.result()
           ^^^^^^^^^^^^^^^
  File "/home/admin_/.local/lib/python3.12/site-packages/uvicorn/server.py", line 71, in serve
    await self._serve(sockets)
  File "/home/admin_/.local/lib/python3.12/site-packages/uvicorn/server.py", line 78, in _serve
    config.load()
  File "/home/admin_/.local/lib/python3.12/site-packages/uvicorn/config.py", line 438, in load
    self.loaded_app = import_from_string(self.app)
                      ^^^^^^^^^^^^^^^^^^^^^^^^^^^^
  File "/home/admin_/.local/lib/python3.12/site-packages/uvicorn/importer.py", line 19, in import_from_string
    module = importlib.import_module(module_str)
             ^^^^^^^^^^^^^^^^^^^^^^^^^^^^^^^^^^^
  File "/usr/lib/python3.12/importlib/__init__.py", line 90, in import_module
    return _bootstrap._gcd_import(name[level:], package, level)
           ^^^^^^^^^^^^^^^^^^^^^^^^^^^^^^^^^^^^^^^^^^^^^^^^^^^^
  File "<frozen importlib._bootstrap>", line 1387, in _gcd_import
  File "<frozen importlib._bootstrap>", line 1360, in _find_and_load
  File "<frozen importlib._bootstrap>", line 1331, in _find_and_load_unlocked
  File "<frozen importlib._bootstrap>", line 935, in _load_unlocked
  File "<frozen importlib._bootstrap_external>", line 991, in exec_module
  File "<frozen importlib._bootstrap_external>", line 1129, in get_code
  File "<frozen importlib._bootstrap_external>", line 1059, in source_to_code
  File "<frozen importlib._bootstrap>", line 488, in _call_with_frames_removed
  File "/home/admin_/final_demo/capi/demo-gen-capi/backend/api.py", line 159
    uvicorn.run(app, host="0.0.0.0", port=8000)/{data_agent_id}']
                                                               ^
SyntaxError: unterminated string literal (detected at line 159)
WARNING:  StatReload detected changes in 'api.py'. Reloading...
INFO:     Started server process [14314]
INFO:     Waiting for application startup.
ERROR:    Traceback (most recent call last):
  File "/home/admin_/.local/lib/python3.12/site-packages/starlette/routing.py", line 694, in lifespan
    async with self.lifespan_context(app) as maybe_state:
  File "/home/admin_/.local/lib/python3.12/site-packages/starlette/routing.py", line 571, in __aenter__
    await self._router.startup()
  File "/home/admin_/.local/lib/python3.12/site-packages/starlette/routing.py", line 673, in startup
    handler()
  File "/home/admin_/final_demo/capi/demo-gen-capi/backend/api.py", line 141, in startup_event
    create_data_agent()
  File "/home/admin_/final_demo/capi/demo-gen-capi/backend/api.py", line 49, in create_data_agent
    table_names = table_names
                  ^^^^^^^^^^^
UnboundLocalError: cannot access local variable 'table_names' where it is not associated with a value

ERROR:    Application startup failed. Exiting.
WARNING:  StatReload detected changes in 'api.py'. Reloading...
INFO:     Started server process [14361]
INFO:     Waiting for application startup.
INFO:     Application startup complete.
ERROR:    Traceback (most recent call last):
  File "/usr/lib/python3.12/asyncio/runners.py", line 194, in run
    return runner.run(main)
           ^^^^^^^^^^^^^^^^
  File "/usr/lib/python3.12/asyncio/runners.py", line 118, in run
    return self._loop.run_until_complete(task)
           ^^^^^^^^^^^^^^^^^^^^^^^^^^^^^^^^^^^
  File "/usr/lib/python3.12/asyncio/base_events.py", line 687, in run_until_complete
    return future.result()
           ^^^^^^^^^^^^^^^
  File "/home/admin_/.local/lib/python3.12/site-packages/uvicorn/server.py", line 71, in serve
    await self._serve(sockets)
  File "/home/admin_/.local/lib/python3.12/site-packages/uvicorn/server.py", line 86, in _serve
    await self.startup(sockets=sockets)
  File "/home/admin_/.local/lib/python3.12/site-packages/uvicorn/server.py", line 136, in startup
    server = await loop.create_server(create_protocol, sock=sock, ssl=config.ssl, backlog=config.backlog)
             ^^^^^^^^^^^^^^^^^^^^^^^^^^^^^^^^^^^^^^^^^^^^^^^^^^^^^^^^^^^^^^^^^^^^^^^^^^^^^^^^^^^^^^^^^^^^
  File "/usr/lib/python3.12/asyncio/base_events.py", line 1597, in create_server
    server._start_serving()
  File "/usr/lib/python3.12/asyncio/base_events.py", line 317, in _start_serving
    sock.listen(self._backlog)
OSError: [Errno 98] Address already in use

During handling of the above exception, another exception occurred:

Traceback (most recent call last):
  File "/home/admin_/.local/lib/python3.12/site-packages/starlette/routing.py", line 701, in lifespan
    await receive()
  File "/home/admin_/.local/lib/python3.12/site-packages/uvicorn/lifespan/on.py", line 137, in receive
    return await self.receive_queue.get()
           ^^^^^^^^^^^^^^^^^^^^^^^^^^^^^^
  File "/usr/lib/python3.12/asyncio/queues.py", line 158, in get
    await getter
asyncio.exceptions.CancelledError

Process SpawnProcess-6:
Traceback (most recent call last):
  File "/usr/lib/python3.12/multiprocessing/process.py", line 314, in _bootstrap
    self.run()
  File "/usr/lib/python3.12/multiprocessing/process.py", line 108, in run
    self._target(*self._args, **self._kwargs)
  File "/home/admin_/.local/lib/python3.12/site-packages/uvicorn/_subprocess.py", line 80, in subprocess_started
    target(sockets=sockets)
  File "/home/admin_/.local/lib/python3.12/site-packages/uvicorn/server.py", line 67, in run
    return asyncio_run(self.serve(sockets=sockets), loop_factory=self.config.get_loop_factory())
           ^^^^^^^^^^^^^^^^^^^^^^^^^^^^^^^^^^^^^^^^^^^^^^^^^^^^^^^^^^^^^^^^^^^^^^^^^^^^^^^^^^^^^
  File "/usr/lib/python3.12/asyncio/runners.py", line 194, in run
    return runner.run(main)
           ^^^^^^^^^^^^^^^^
  File "/usr/lib/python3.12/asyncio/runners.py", line 118, in run
    return self._loop.run_until_complete(task)
           ^^^^^^^^^^^^^^^^^^^^^^^^^^^^^^^^^^^
  File "/usr/lib/python3.12/asyncio/base_events.py", line 687, in run_until_complete
    return future.result()
           ^^^^^^^^^^^^^^^
  File "/home/admin_/.local/lib/python3.12/site-packages/uvicorn/server.py", line 71, in serve
    await self._serve(sockets)
  File "/home/admin_/.local/lib/python3.12/site-packages/uvicorn/server.py", line 86, in _serve
    await self.startup(sockets=sockets)
  File "/home/admin_/.local/lib/python3.12/site-packages/uvicorn/server.py", line 136, in startup
    server = await loop.create_server(create_protocol, sock=sock, ssl=config.ssl, backlog=config.backlog)
             ^^^^^^^^^^^^^^^^^^^^^^^^^^^^^^^^^^^^^^^^^^^^^^^^^^^^^^^^^^^^^^^^^^^^^^^^^^^^^^^^^^^^^^^^^^^^
  File "/usr/lib/python3.12/asyncio/base_events.py", line 1597, in create_server
    server._start_serving()
  File "/usr/lib/python3.12/asyncio/base_events.py", line 317, in _start_serving
    sock.listen(self._backlog)
OSError: [Errno 98] Address already in use
Data agent 'default_agent' already exists.
WARNING:  StatReload detected changes in 'api.py'. Reloading...
INFO:     Started server process [14559]
INFO:     Waiting for application startup.
INFO:     Application startup complete.
ERROR:    Traceback (most recent call last):
  File "/usr/lib/python3.12/asyncio/runners.py", line 194, in run
    return runner.run(main)
           ^^^^^^^^^^^^^^^^
  File "/usr/lib/python3.12/asyncio/runners.py", line 118, in run
    return self._loop.run_until_complete(task)
           ^^^^^^^^^^^^^^^^^^^^^^^^^^^^^^^^^^^
  File "/usr/lib/python3.12/asyncio/base_events.py", line 687, in run_until_complete
    return future.result()
           ^^^^^^^^^^^^^^^
  File "/home/admin_/.local/lib/python3.12/site-packages/uvicorn/server.py", line 71, in serve
    await self._serve(sockets)
  File "/home/admin_/.local/lib/python3.12/site-packages/uvicorn/server.py", line 86, in _serve
    await self.startup(sockets=sockets)
  File "/home/admin_/.local/lib/python3.12/site-packages/uvicorn/server.py", line 136, in startup
    server = await loop.create_server(create_protocol, sock=sock, ssl=config.ssl, backlog=config.backlog)
             ^^^^^^^^^^^^^^^^^^^^^^^^^^^^^^^^^^^^^^^^^^^^^^^^^^^^^^^^^^^^^^^^^^^^^^^^^^^^^^^^^^^^^^^^^^^^
  File "/usr/lib/python3.12/asyncio/base_events.py", line 1597, in create_server
    server._start_serving()
  File "/usr/lib/python3.12/asyncio/base_events.py", line 317, in _start_serving
    sock.listen(self._backlog)
OSError: [Errno 98] Address already in use

During handling of the above exception, another exception occurred:

Traceback (most recent call last):
  File "/home/admin_/.local/lib/python3.12/site-packages/starlette/routing.py", line 701, in lifespan
    await receive()
  File "/home/admin_/.local/lib/python3.12/site-packages/uvicorn/lifespan/on.py", line 137, in receive
    return await self.receive_queue.get()
           ^^^^^^^^^^^^^^^^^^^^^^^^^^^^^^
  File "/usr/lib/python3.12/asyncio/queues.py", line 158, in get
    await getter
asyncio.exceptions.CancelledError

Process SpawnProcess-7:
Traceback (most recent call last):
  File "/usr/lib/python3.12/multiprocessing/process.py", line 314, in _bootstrap
    self.run()
  File "/usr/lib/python3.12/multiprocessing/process.py", line 108, in run
    self._target(*self._args, **self._kwargs)
  File "/home/admin_/.local/lib/python3.12/site-packages/uvicorn/_subprocess.py", line 80, in subprocess_started
    target(sockets=sockets)
  File "/home/admin_/.local/lib/python3.12/site-packages/uvicorn/server.py", line 67, in run
    return asyncio_run(self.serve(sockets=sockets), loop_factory=self.config.get_loop_factory())
           ^^^^^^^^^^^^^^^^^^^^^^^^^^^^^^^^^^^^^^^^^^^^^^^^^^^^^^^^^^^^^^^^^^^^^^^^^^^^^^^^^^^^^
  File "/usr/lib/python3.12/asyncio/runners.py", line 194, in run
    return runner.run(main)
           ^^^^^^^^^^^^^^^^
  File "/usr/lib/python3.12/asyncio/runners.py", line 118, in run
    return self._loop.run_until_complete(task)
           ^^^^^^^^^^^^^^^^^^^^^^^^^^^^^^^^^^^
  File "/usr/lib/python3.12/asyncio/base_events.py", line 687, in run_until_complete
    return future.result()
           ^^^^^^^^^^^^^^^
  File "/home/admin_/.local/lib/python3.12/site-packages/uvicorn/server.py", line 71, in serve
    await self._serve(sockets)
  File "/home/admin_/.local/lib/python3.12/site-packages/uvicorn/server.py", line 86, in _serve
    await self.startup(sockets=sockets)
  File "/home/admin_/.local/lib/python3.12/site-packages/uvicorn/server.py", line 136, in startup
    server = await loop.create_server(create_protocol, sock=sock, ssl=config.ssl, backlog=config.backlog)
             ^^^^^^^^^^^^^^^^^^^^^^^^^^^^^^^^^^^^^^^^^^^^^^^^^^^^^^^^^^^^^^^^^^^^^^^^^^^^^^^^^^^^^^^^^^^^
  File "/usr/lib/python3.12/asyncio/base_events.py", line 1597, in create_server
    server._start_serving()
  File "/usr/lib/python3.12/asyncio/base_events.py", line 317, in _start_serving
    sock.listen(self._backlog)
OSError: [Errno 98] Address already in use
Data agent 'default_agent' already exists.
WARNING:  StatReload detected changes in 'api.py'. Reloading...
INFO:     Started server process [14714]
INFO:     Waiting for application startup.
INFO:     Application startup complete.
ERROR:    Traceback (most recent call last):
  File "/usr/lib/python3.12/asyncio/runners.py", line 194, in run
    return runner.run(main)
           ^^^^^^^^^^^^^^^^
  File "/usr/lib/python3.12/asyncio/runners.py", line 118, in run
    return self._loop.run_until_complete(task)
           ^^^^^^^^^^^^^^^^^^^^^^^^^^^^^^^^^^^
  File "/usr/lib/python3.12/asyncio/base_events.py", line 687, in run_until_complete
    return future.result()
           ^^^^^^^^^^^^^^^
  File "/home/admin_/.local/lib/python3.12/site-packages/uvicorn/server.py", line 71, in serve
    await self._serve(sockets)
  File "/home/admin_/.local/lib/python3.12/site-packages/uvicorn/server.py", line 86, in _serve
    await self.startup(sockets=sockets)
  File "/home/admin_/.local/lib/python3.12/site-packages/uvicorn/server.py", line 136, in startup
    server = await loop.create_server(create_protocol, sock=sock, ssl=config.ssl, backlog=config.backlog)
             ^^^^^^^^^^^^^^^^^^^^^^^^^^^^^^^^^^^^^^^^^^^^^^^^^^^^^^^^^^^^^^^^^^^^^^^^^^^^^^^^^^^^^^^^^^^^
  File "/usr/lib/python3.12/asyncio/base_events.py", line 1597, in create_server
    server._start_serving()
  File "/usr/lib/python3.12/asyncio/base_events.py", line 317, in _start_serving
    sock.listen(self._backlog)
OSError: [Errno 98] Address already in use

During handling of the above exception, another exception occurred:

Traceback (most recent call last):
  File "/home/admin_/.local/lib/python3.12/site-packages/starlette/routing.py", line 701, in lifespan
    await receive()
  File "/home/admin_/.local/lib/python3.12/site-packages/uvicorn/lifespan/on.py", line 137, in receive
    return await self.receive_queue.get()
           ^^^^^^^^^^^^^^^^^^^^^^^^^^^^^^
  File "/usr/lib/python3.12/asyncio/queues.py", line 158, in get
    await getter
asyncio.exceptions.CancelledError

Process SpawnProcess-8:
Traceback (most recent call last):
  File "/usr/lib/python3.12/multiprocessing/process.py", line 314, in _bootstrap
    self.run()
  File "/usr/lib/python3.12/multiprocessing/process.py", line 108, in run
    self._target(*self._args, **self._kwargs)
  File "/home/admin_/.local/lib/python3.12/site-packages/uvicorn/_subprocess.py", line 80, in subprocess_started
    target(sockets=sockets)
  File "/home/admin_/.local/lib/python3.12/site-packages/uvicorn/server.py", line 67, in run
    return asyncio_run(self.serve(sockets=sockets), loop_factory=self.config.get_loop_factory())
           ^^^^^^^^^^^^^^^^^^^^^^^^^^^^^^^^^^^^^^^^^^^^^^^^^^^^^^^^^^^^^^^^^^^^^^^^^^^^^^^^^^^^^
  File "/usr/lib/python3.12/asyncio/runners.py", line 194, in run
    return runner.run(main)
           ^^^^^^^^^^^^^^^^
  File "/usr/lib/python3.12/asyncio/runners.py", line 118, in run
    return self._loop.run_until_complete(task)
           ^^^^^^^^^^^^^^^^^^^^^^^^^^^^^^^^^^^
  File "/usr/lib/python3.12/asyncio/base_events.py", line 687, in run_until_complete
    return future.result()
           ^^^^^^^^^^^^^^^
  File "/home/admin_/.local/lib/python3.12/site-packages/uvicorn/server.py", line 71, in serve
    await self._serve(sockets)
  File "/home/admin_/.local/lib/python3.12/site-packages/uvicorn/server.py", line 86, in _serve
    await self.startup(sockets=sockets)
  File "/home/admin_/.local/lib/python3.12/site-packages/uvicorn/server.py", line 136, in startup
    server = await loop.create_server(create_protocol, sock=sock, ssl=config.ssl, backlog=config.backlog)
             ^^^^^^^^^^^^^^^^^^^^^^^^^^^^^^^^^^^^^^^^^^^^^^^^^^^^^^^^^^^^^^^^^^^^^^^^^^^^^^^^^^^^^^^^^^^^
  File "/usr/lib/python3.12/asyncio/base_events.py", line 1597, in create_server
    server._start_serving()
  File "/usr/lib/python3.12/asyncio/base_events.py", line 317, in _start_serving
    sock.listen(self._backlog)
OSError: [Errno 98] Address already in use
Data agent 'default_agent' already exists.
WARNING:  StatReload detected changes in 'api.py'. Reloading...
INFO:     Started server process [14829]
INFO:     Waiting for application startup.
INFO:     Application startup complete.
ERROR:    Traceback (most recent call last):
  File "/usr/lib/python3.12/asyncio/runners.py", line 194, in run
    return runner.run(main)
           ^^^^^^^^^^^^^^^^
  File "/usr/lib/python3.12/asyncio/runners.py", line 118, in run
    return self._loop.run_until_complete(task)
           ^^^^^^^^^^^^^^^^^^^^^^^^^^^^^^^^^^^
  File "/usr/lib/python3.12/asyncio/base_events.py", line 687, in run_until_complete
    return future.result()
           ^^^^^^^^^^^^^^^
  File "/home/admin_/.local/lib/python3.12/site-packages/uvicorn/server.py", line 71, in serve
    await self._serve(sockets)
  File "/home/admin_/.local/lib/python3.12/site-packages/uvicorn/server.py", line 86, in _serve
    await self.startup(sockets=sockets)
  File "/home/admin_/.local/lib/python3.12/site-packages/uvicorn/server.py", line 136, in startup
    server = await loop.create_server(create_protocol, sock=sock, ssl=config.ssl, backlog=config.backlog)
             ^^^^^^^^^^^^^^^^^^^^^^^^^^^^^^^^^^^^^^^^^^^^^^^^^^^^^^^^^^^^^^^^^^^^^^^^^^^^^^^^^^^^^^^^^^^^
  File "/usr/lib/python3.12/asyncio/base_events.py", line 1597, in create_server
    server._start_serving()
  File "/usr/lib/python3.12/asyncio/base_events.py", line 317, in _start_serving
    sock.listen(self._backlog)
OSError: [Errno 98] Address already in use

During handling of the above exception, another exception occurred:

Traceback (most recent call last):
  File "/home/admin_/.local/lib/python3.12/site-packages/starlette/routing.py", line 701, in lifespan
    await receive()
  File "/home/admin_/.local/lib/python3.12/site-packages/uvicorn/lifespan/on.py", line 137, in receive
    return await self.receive_queue.get()
           ^^^^^^^^^^^^^^^^^^^^^^^^^^^^^^
  File "/usr/lib/python3.12/asyncio/queues.py", line 158, in get
    await getter
asyncio.exceptions.CancelledError

Process SpawnProcess-9:
Traceback (most recent call last):
  File "/usr/lib/python3.12/multiprocessing/process.py", line 314, in _bootstrap
    self.run()
  File "/usr/lib/python3.12/multiprocessing/process.py", line 108, in run
    self._target(*self._args, **self._kwargs)
  File "/home/admin_/.local/lib/python3.12/site-packages/uvicorn/_subprocess.py", line 80, in subprocess_started
    target(sockets=sockets)
  File "/home/admin_/.local/lib/python3.12/site-packages/uvicorn/server.py", line 67, in run
    return asyncio_run(self.serve(sockets=sockets), loop_factory=self.config.get_loop_factory())
           ^^^^^^^^^^^^^^^^^^^^^^^^^^^^^^^^^^^^^^^^^^^^^^^^^^^^^^^^^^^^^^^^^^^^^^^^^^^^^^^^^^^^^
  File "/usr/lib/python3.12/asyncio/runners.py", line 194, in run
    return runner.run(main)
           ^^^^^^^^^^^^^^^^
  File "/usr/lib/python3.12/asyncio/runners.py", line 118, in run
    return self._loop.run_until_complete(task)
           ^^^^^^^^^^^^^^^^^^^^^^^^^^^^^^^^^^^
  File "/usr/lib/python3.12/asyncio/base_events.py", line 687, in run_until_complete
    return future.result()
           ^^^^^^^^^^^^^^^
  File "/home/admin_/.local/lib/python3.12/site-packages/uvicorn/server.py", line 71, in serve
    await self._serve(sockets)
  File "/home/admin_/.local/lib/python3.12/site-packages/uvicorn/server.py", line 86, in _serve
    await self.startup(sockets=sockets)
  File "/home/admin_/.local/lib/python3.12/site-packages/uvicorn/server.py", line 136, in startup
    server = await loop.create_server(create_protocol, sock=sock, ssl=config.ssl, backlog=config.backlog)
             ^^^^^^^^^^^^^^^^^^^^^^^^^^^^^^^^^^^^^^^^^^^^^^^^^^^^^^^^^^^^^^^^^^^^^^^^^^^^^^^^^^^^^^^^^^^^
  File "/usr/lib/python3.12/asyncio/base_events.py", line 1597, in create_server
    server._start_serving()
  File "/usr/lib/python3.12/asyncio/base_events.py", line 317, in _start_serving
    sock.listen(self._backlog)
OSError: [Errno 98] Address already in use
Data agent 'default_agent' already exists.
WARNING:  StatReload detected changes in 'api.py'. Reloading...
Process SpawnProcess-10:
Traceback (most recent call last):
  File "/usr/lib/python3.12/multiprocessing/process.py", line 314, in _bootstrap
    self.run()
  File "/usr/lib/python3.12/multiprocessing/process.py", line 108, in run
    self._target(*self._args, **self._kwargs)
  File "/home/admin_/.local/lib/python3.12/site-packages/uvicorn/_subprocess.py", line 80, in subprocess_started
    target(sockets=sockets)
  File "/home/admin_/.local/lib/python3.12/site-packages/uvicorn/server.py", line 67, in run
    return asyncio_run(self.serve(sockets=sockets), loop_factory=self.config.get_loop_factory())
           ^^^^^^^^^^^^^^^^^^^^^^^^^^^^^^^^^^^^^^^^^^^^^^^^^^^^^^^^^^^^^^^^^^^^^^^^^^^^^^^^^^^^^
  File "/usr/lib/python3.12/asyncio/runners.py", line 194, in run
    return runner.run(main)
           ^^^^^^^^^^^^^^^^
  File "/usr/lib/python3.12/asyncio/runners.py", line 118, in run
    return self._loop.run_until_complete(task)
           ^^^^^^^^^^^^^^^^^^^^^^^^^^^^^^^^^^^
  File "/usr/lib/python3.12/asyncio/base_events.py", line 687, in run_until_complete
    return future.result()
           ^^^^^^^^^^^^^^^
  File "/home/admin_/.local/lib/python3.12/site-packages/uvicorn/server.py", line 71, in serve
    await self._serve(sockets)
  File "/home/admin_/.local/lib/python3.12/site-packages/uvicorn/server.py", line 78, in _serve
    config.load()
  File "/home/admin_/.local/lib/python3.12/site-packages/uvicorn/config.py", line 438, in load
    self.loaded_app = import_from_string(self.app)
                      ^^^^^^^^^^^^^^^^^^^^^^^^^^^^
  File "/home/admin_/.local/lib/python3.12/site-packages/uvicorn/importer.py", line 19, in import_from_string
    module = importlib.import_module(module_str)
             ^^^^^^^^^^^^^^^^^^^^^^^^^^^^^^^^^^^
  File "/usr/lib/python3.12/importlib/__init__.py", line 90, in import_module
    return _bootstrap._gcd_import(name[level:], package, level)
           ^^^^^^^^^^^^^^^^^^^^^^^^^^^^^^^^^^^^^^^^^^^^^^^^^^^^
  File "<frozen importlib._bootstrap>", line 1387, in _gcd_import
  File "<frozen importlib._bootstrap>", line 1360, in _find_and_load
  File "<frozen importlib._bootstrap>", line 1331, in _find_and_load_unlocked
  File "<frozen importlib._bootstrap>", line 935, in _load_unlocked
  File "<frozen importlib._bootstrap_external>", line 991, in exec_module
  File "<frozen importlib._bootstrap_external>", line 1129, in get_code
  File "<frozen importlib._bootstrap_external>", line 1059, in source_to_code
  File "<frozen importlib._bootstrap>", line 488, in _call_with_frames_removed
  File "/home/admin_/final_demo/capi/demo-gen-capi/backend/api.py", line 208
    uvicorn.run(app, host="0.0.0.0", port=8000)_main__":
                                                      ^
SyntaxError: unterminated string literal (detected at line 208)
WARNING:  StatReload detected changes in 'api.py'. Reloading...
INFO:     Started server process [14921]
INFO:     Waiting for application startup.
INFO:     Application startup complete.
ERROR:    Traceback (most recent call last):
  File "/usr/lib/python3.12/asyncio/runners.py", line 194, in run
    return runner.run(main)
           ^^^^^^^^^^^^^^^^
  File "/usr/lib/python3.12/asyncio/runners.py", line 118, in run
    return self._loop.run_until_complete(task)
           ^^^^^^^^^^^^^^^^^^^^^^^^^^^^^^^^^^^
  File "/usr/lib/python3.12/asyncio/base_events.py", line 687, in run_until_complete
    return future.result()
           ^^^^^^^^^^^^^^^
  File "/home/admin_/.local/lib/python3.12/site-packages/uvicorn/server.py", line 71, in serve
    await self._serve(sockets)
  File "/home/admin_/.local/lib/python3.12/site-packages/uvicorn/server.py", line 86, in _serve
    await self.startup(sockets=sockets)
  File "/home/admin_/.local/lib/python3.12/site-packages/uvicorn/server.py", line 136, in startup
    server = await loop.create_server(create_protocol, sock=sock, ssl=config.ssl, backlog=config.backlog)
             ^^^^^^^^^^^^^^^^^^^^^^^^^^^^^^^^^^^^^^^^^^^^^^^^^^^^^^^^^^^^^^^^^^^^^^^^^^^^^^^^^^^^^^^^^^^^
  File "/usr/lib/python3.12/asyncio/base_events.py", line 1597, in create_server
    server._start_serving()
  File "/usr/lib/python3.12/asyncio/base_events.py", line 317, in _start_serving
    sock.listen(self._backlog)
OSError: [Errno 98] Address already in use

During handling of the above exception, another exception occurred:

Traceback (most recent call last):
  File "/home/admin_/.local/lib/python3.12/site-packages/starlette/routing.py", line 701, in lifespan
    await receive()
  File "/home/admin_/.local/lib/python3.12/site-packages/uvicorn/lifespan/on.py", line 137, in receive
    return await self.receive_queue.get()
           ^^^^^^^^^^^^^^^^^^^^^^^^^^^^^^
  File "/usr/lib/python3.12/asyncio/queues.py", line 158, in get
    await getter
asyncio.exceptions.CancelledError

Process SpawnProcess-11:
Traceback (most recent call last):
  File "/usr/lib/python3.12/multiprocessing/process.py", line 314, in _bootstrap
    self.run()
  File "/usr/lib/python3.12/multiprocessing/process.py", line 108, in run
    self._target(*self._args, **self._kwargs)
  File "/home/admin_/.local/lib/python3.12/site-packages/uvicorn/_subprocess.py", line 80, in subprocess_started
    target(sockets=sockets)
  File "/home/admin_/.local/lib/python3.12/site-packages/uvicorn/server.py", line 67, in run
    return asyncio_run(self.serve(sockets=sockets), loop_factory=self.config.get_loop_factory())
           ^^^^^^^^^^^^^^^^^^^^^^^^^^^^^^^^^^^^^^^^^^^^^^^^^^^^^^^^^^^^^^^^^^^^^^^^^^^^^^^^^^^^^
  File "/usr/lib/python3.12/asyncio/runners.py", line 194, in run
    return runner.run(main)
           ^^^^^^^^^^^^^^^^
  File "/usr/lib/python3.12/asyncio/runners.py", line 118, in run
    return self._loop.run_until_complete(task)
           ^^^^^^^^^^^^^^^^^^^^^^^^^^^^^^^^^^^
  File "/usr/lib/python3.12/asyncio/base_events.py", line 687, in run_until_complete
    return future.result()
           ^^^^^^^^^^^^^^^
  File "/home/admin_/.local/lib/python3.12/site-packages/uvicorn/server.py", line 71, in serve
    await self._serve(sockets)
  File "/home/admin_/.local/lib/python3.12/site-packages/uvicorn/server.py", line 86, in _serve
    await self.startup(sockets=sockets)
  File "/home/admin_/.local/lib/python3.12/site-packages/uvicorn/server.py", line 136, in startup
    server = await loop.create_server(create_protocol, sock=sock, ssl=config.ssl, backlog=config.backlog)
             ^^^^^^^^^^^^^^^^^^^^^^^^^^^^^^^^^^^^^^^^^^^^^^^^^^^^^^^^^^^^^^^^^^^^^^^^^^^^^^^^^^^^^^^^^^^^
  File "/usr/lib/python3.12/asyncio/base_events.py", line 1597, in create_server
    server._start_serving()
  File "/usr/lib/python3.12/asyncio/base_events.py", line 317, in _start_serving
    sock.listen(self._backlog)
OSError: [Errno 98] Address already in use
Data agent 'default_agent' already exists.
WARNING:  StatReload detected changes in 'api.py'. Reloading...
INFO:     Started server process [15011]
INFO:     Waiting for application startup.
INFO:     Application startup complete.
ERROR:    Traceback (most recent call last):
  File "/usr/lib/python3.12/asyncio/runners.py", line 194, in run
    return runner.run(main)
           ^^^^^^^^^^^^^^^^
  File "/usr/lib/python3.12/asyncio/runners.py", line 118, in run
    return self._loop.run_until_complete(task)
           ^^^^^^^^^^^^^^^^^^^^^^^^^^^^^^^^^^^
  File "/usr/lib/python3.12/asyncio/base_events.py", line 687, in run_until_complete
    return future.result()
           ^^^^^^^^^^^^^^^
  File "/home/admin_/.local/lib/python3.12/site-packages/uvicorn/server.py", line 71, in serve
    await self._serve(sockets)
  File "/home/admin_/.local/lib/python3.12/site-packages/uvicorn/server.py", line 86, in _serve
    await self.startup(sockets=sockets)
  File "/home/admin_/.local/lib/python3.12/site-packages/uvicorn/server.py", line 136, in startup
    server = await loop.create_server(create_protocol, sock=sock, ssl=config.ssl, backlog=config.backlog)
             ^^^^^^^^^^^^^^^^^^^^^^^^^^^^^^^^^^^^^^^^^^^^^^^^^^^^^^^^^^^^^^^^^^^^^^^^^^^^^^^^^^^^^^^^^^^^
  File "/usr/lib/python3.12/asyncio/base_events.py", line 1597, in create_server
    server._start_serving()
  File "/usr/lib/python3.12/asyncio/base_events.py", line 317, in _start_serving
    sock.listen(self._backlog)
OSError: [Errno 98] Address already in use

During handling of the above exception, another exception occurred:

Traceback (most recent call last):
  File "/home/admin_/.local/lib/python3.12/site-packages/starlette/routing.py", line 701, in lifespan
    await receive()
  File "/home/admin_/.local/lib/python3.12/site-packages/uvicorn/lifespan/on.py", line 137, in receive
    return await self.receive_queue.get()
           ^^^^^^^^^^^^^^^^^^^^^^^^^^^^^^
  File "/usr/lib/python3.12/asyncio/queues.py", line 158, in get
    await getter
asyncio.exceptions.CancelledError

Process SpawnProcess-12:
Traceback (most recent call last):
  File "/usr/lib/python3.12/multiprocessing/process.py", line 314, in _bootstrap
    self.run()
  File "/usr/lib/python3.12/multiprocessing/process.py", line 108, in run
    self._target(*self._args, **self._kwargs)
  File "/home/admin_/.local/lib/python3.12/site-packages/uvicorn/_subprocess.py", line 80, in subprocess_started
    target(sockets=sockets)
  File "/home/admin_/.local/lib/python3.12/site-packages/uvicorn/server.py", line 67, in run
    return asyncio_run(self.serve(sockets=sockets), loop_factory=self.config.get_loop_factory())
           ^^^^^^^^^^^^^^^^^^^^^^^^^^^^^^^^^^^^^^^^^^^^^^^^^^^^^^^^^^^^^^^^^^^^^^^^^^^^^^^^^^^^^
  File "/usr/lib/python3.12/asyncio/runners.py", line 194, in run
    return runner.run(main)
           ^^^^^^^^^^^^^^^^
  File "/usr/lib/python3.12/asyncio/runners.py", line 118, in run
    return self._loop.run_until_complete(task)
           ^^^^^^^^^^^^^^^^^^^^^^^^^^^^^^^^^^^
  File "/usr/lib/python3.12/asyncio/base_events.py", line 687, in run_until_complete
    return future.result()
           ^^^^^^^^^^^^^^^
  File "/home/admin_/.local/lib/python3.12/site-packages/uvicorn/server.py", line 71, in serve
    await self._serve(sockets)
  File "/home/admin_/.local/lib/python3.12/site-packages/uvicorn/server.py", line 86, in _serve
    await self.startup(sockets=sockets)
  File "/home/admin_/.local/lib/python3.12/site-packages/uvicorn/server.py", line 136, in startup
    server = await loop.create_server(create_protocol, sock=sock, ssl=config.ssl, backlog=config.backlog)
             ^^^^^^^^^^^^^^^^^^^^^^^^^^^^^^^^^^^^^^^^^^^^^^^^^^^^^^^^^^^^^^^^^^^^^^^^^^^^^^^^^^^^^^^^^^^^
  File "/usr/lib/python3.12/asyncio/base_events.py", line 1597, in create_server
    server._start_serving()
  File "/usr/lib/python3.12/asyncio/base_events.py", line 317, in _start_serving
    sock.listen(self._backlog)
OSError: [Errno 98] Address already in use
Data agent 'default_agent' already exists.
WARNING:  StatReload detected changes in 'api.py'. Reloading...
INFO:     Started server process [15079]
INFO:     Waiting for application startup.
INFO:     Application startup complete.
ERROR:    Traceback (most recent call last):
  File "/usr/lib/python3.12/asyncio/runners.py", line 194, in run
    return runner.run(main)
           ^^^^^^^^^^^^^^^^
  File "/usr/lib/python3.12/asyncio/runners.py", line 118, in run
    return self._loop.run_until_complete(task)
           ^^^^^^^^^^^^^^^^^^^^^^^^^^^^^^^^^^^
  File "/usr/lib/python3.12/asyncio/base_events.py", line 687, in run_until_complete
    return future.result()
           ^^^^^^^^^^^^^^^
  File "/home/admin_/.local/lib/python3.12/site-packages/uvicorn/server.py", line 71, in serve
    await self._serve(sockets)
  File "/home/admin_/.local/lib/python3.12/site-packages/uvicorn/server.py", line 86, in _serve
    await self.startup(sockets=sockets)
  File "/home/admin_/.local/lib/python3.12/site-packages/uvicorn/server.py", line 136, in startup
    server = await loop.create_server(create_protocol, sock=sock, ssl=config.ssl, backlog=config.backlog)
             ^^^^^^^^^^^^^^^^^^^^^^^^^^^^^^^^^^^^^^^^^^^^^^^^^^^^^^^^^^^^^^^^^^^^^^^^^^^^^^^^^^^^^^^^^^^^
  File "/usr/lib/python3.12/asyncio/base_events.py", line 1597, in create_server
    server._start_serving()
  File "/usr/lib/python3.12/asyncio/base_events.py", line 317, in _start_serving
    sock.listen(self._backlog)
OSError: [Errno 98] Address already in use

During handling of the above exception, another exception occurred:

Traceback (most recent call last):
  File "/home/admin_/.local/lib/python3.12/site-packages/starlette/routing.py", line 701, in lifespan
    await receive()
  File "/home/admin_/.local/lib/python3.12/site-packages/uvicorn/lifespan/on.py", line 137, in receive
    return await self.receive_queue.get()
           ^^^^^^^^^^^^^^^^^^^^^^^^^^^^^^
  File "/usr/lib/python3.12/asyncio/queues.py", line 158, in get
    await getter
asyncio.exceptions.CancelledError

Process SpawnProcess-13:
Traceback (most recent call last):
  File "/usr/lib/python3.12/multiprocessing/process.py", line 314, in _bootstrap
    self.run()
  File "/usr/lib/python3.12/multiprocessing/process.py", line 108, in run
    self._target(*self._args, **self._kwargs)
  File "/home/admin_/.local/lib/python3.12/site-packages/uvicorn/_subprocess.py", line 80, in subprocess_started
    target(sockets=sockets)
  File "/home/admin_/.local/lib/python3.12/site-packages/uvicorn/server.py", line 67, in run
    return asyncio_run(self.serve(sockets=sockets), loop_factory=self.config.get_loop_factory())
           ^^^^^^^^^^^^^^^^^^^^^^^^^^^^^^^^^^^^^^^^^^^^^^^^^^^^^^^^^^^^^^^^^^^^^^^^^^^^^^^^^^^^^
  File "/usr/lib/python3.12/asyncio/runners.py", line 194, in run
    return runner.run(main)
           ^^^^^^^^^^^^^^^^
  File "/usr/lib/python3.12/asyncio/runners.py", line 118, in run
    return self._loop.run_until_complete(task)
           ^^^^^^^^^^^^^^^^^^^^^^^^^^^^^^^^^^^
  File "/usr/lib/python3.12/asyncio/base_events.py", line 687, in run_until_complete
    return future.result()
           ^^^^^^^^^^^^^^^
  File "/home/admin_/.local/lib/python3.12/site-packages/uvicorn/server.py", line 71, in serve
    await self._serve(sockets)
  File "/home/admin_/.local/lib/python3.12/site-packages/uvicorn/server.py", line 86, in _serve
    await self.startup(sockets=sockets)
  File "/home/admin_/.local/lib/python3.12/site-packages/uvicorn/server.py", line 136, in startup
    server = await loop.create_server(create_protocol, sock=sock, ssl=config.ssl, backlog=config.backlog)
             ^^^^^^^^^^^^^^^^^^^^^^^^^^^^^^^^^^^^^^^^^^^^^^^^^^^^^^^^^^^^^^^^^^^^^^^^^^^^^^^^^^^^^^^^^^^^
  File "/usr/lib/python3.12/asyncio/base_events.py", line 1597, in create_server
    server._start_serving()
  File "/usr/lib/python3.12/asyncio/base_events.py", line 317, in _start_serving
    sock.listen(self._backlog)
OSError: [Errno 98] Address already in use
Data agent 'default_agent' already exists.
WARNING:  StatReload detected changes in 'api.py'. Reloading...
INFO:     Started server process [15214]
INFO:     Waiting for application startup.
INFO:     Application startup complete.
ERROR:    Traceback (most recent call last):
  File "/usr/lib/python3.12/asyncio/runners.py", line 194, in run
    return runner.run(main)
           ^^^^^^^^^^^^^^^^
  File "/usr/lib/python3.12/asyncio/runners.py", line 118, in run
    return self._loop.run_until_complete(task)
           ^^^^^^^^^^^^^^^^^^^^^^^^^^^^^^^^^^^
  File "/usr/lib/python3.12/asyncio/base_events.py", line 687, in run_until_complete
    return future.result()
           ^^^^^^^^^^^^^^^
  File "/home/admin_/.local/lib/python3.12/site-packages/uvicorn/server.py", line 71, in serve
    await self._serve(sockets)
  File "/home/admin_/.local/lib/python3.12/site-packages/uvicorn/server.py", line 86, in _serve
    await self.startup(sockets=sockets)
  File "/home/admin_/.local/lib/python3.12/site-packages/uvicorn/server.py", line 136, in startup
    server = await loop.create_server(create_protocol, sock=sock, ssl=config.ssl, backlog=config.backlog)
             ^^^^^^^^^^^^^^^^^^^^^^^^^^^^^^^^^^^^^^^^^^^^^^^^^^^^^^^^^^^^^^^^^^^^^^^^^^^^^^^^^^^^^^^^^^^^
  File "/usr/lib/python3.12/asyncio/base_events.py", line 1597, in create_server
    server._start_serving()
  File "/usr/lib/python3.12/asyncio/base_events.py", line 317, in _start_serving
    sock.listen(self._backlog)
OSError: [Errno 98] Address already in use

During handling of the above exception, another exception occurred:

Traceback (most recent call last):
  File "/home/admin_/.local/lib/python3.12/site-packages/starlette/routing.py", line 701, in lifespan
    await receive()
  File "/home/admin_/.local/lib/python3.12/site-packages/uvicorn/lifespan/on.py", line 137, in receive
    return await self.receive_queue.get()
           ^^^^^^^^^^^^^^^^^^^^^^^^^^^^^^
  File "/usr/lib/python3.12/asyncio/queues.py", line 158, in get
    await getter
asyncio.exceptions.CancelledError

Process SpawnProcess-14:
Traceback (most recent call last):
  File "/usr/lib/python3.12/multiprocessing/process.py", line 314, in _bootstrap
    self.run()
  File "/usr/lib/python3.12/multiprocessing/process.py", line 108, in run
    self._target(*self._args, **self._kwargs)
  File "/home/admin_/.local/lib/python3.12/site-packages/uvicorn/_subprocess.py", line 80, in subprocess_started
    target(sockets=sockets)
  File "/home/admin_/.local/lib/python3.12/site-packages/uvicorn/server.py", line 67, in run
    return asyncio_run(self.serve(sockets=sockets), loop_factory=self.config.get_loop_factory())
           ^^^^^^^^^^^^^^^^^^^^^^^^^^^^^^^^^^^^^^^^^^^^^^^^^^^^^^^^^^^^^^^^^^^^^^^^^^^^^^^^^^^^^
  File "/usr/lib/python3.12/asyncio/runners.py", line 194, in run
    return runner.run(main)
           ^^^^^^^^^^^^^^^^
  File "/usr/lib/python3.12/asyncio/runners.py", line 118, in run
    return self._loop.run_until_complete(task)
           ^^^^^^^^^^^^^^^^^^^^^^^^^^^^^^^^^^^
  File "/usr/lib/python3.12/asyncio/base_events.py", line 687, in run_until_complete
    return future.result()
           ^^^^^^^^^^^^^^^
  File "/home/admin_/.local/lib/python3.12/site-packages/uvicorn/server.py", line 71, in serve
    await self._serve(sockets)
  File "/home/admin_/.local/lib/python3.12/site-packages/uvicorn/server.py", line 86, in _serve
    await self.startup(sockets=sockets)
  File "/home/admin_/.local/lib/python3.12/site-packages/uvicorn/server.py", line 136, in startup
    server = await loop.create_server(create_protocol, sock=sock, ssl=config.ssl, backlog=config.backlog)
             ^^^^^^^^^^^^^^^^^^^^^^^^^^^^^^^^^^^^^^^^^^^^^^^^^^^^^^^^^^^^^^^^^^^^^^^^^^^^^^^^^^^^^^^^^^^^
  File "/usr/lib/python3.12/asyncio/base_events.py", line 1597, in create_server
    server._start_serving()
  File "/usr/lib/python3.12/asyncio/base_events.py", line 317, in _start_serving
    sock.listen(self._backlog)
OSError: [Errno 98] Address already in use
Data agent 'default_agent' already exists.
WARNING:  StatReload detected changes in 'api.py'. Reloading...
INFO:     Started server process [15310]
INFO:     Waiting for application startup.
ERROR:    Traceback (most recent call last):
  File "/usr/local/lib/python3.12/dist-packages/google/api_core/grpc_helpers.py", line 76, in error_remapped_callable
    return callable_(*args, **kwargs)
           ^^^^^^^^^^^^^^^^^^^^^^^^^^
  File "/usr/local/lib/python3.12/dist-packages/grpc/_interceptor.py", line 277, in __call__
    response, ignored_call = self._with_call(
                             ^^^^^^^^^^^^^^^^
  File "/usr/local/lib/python3.12/dist-packages/grpc/_interceptor.py", line 332, in _with_call
    return call.result(), call
           ^^^^^^^^^^^^^
  File "/usr/local/lib/python3.12/dist-packages/grpc/_channel.py", line 440, in result
    raise self
  File "/usr/local/lib/python3.12/dist-packages/grpc/_interceptor.py", line 315, in continuation
    response, call = self._thunk(new_method).with_call(
                     ^^^^^^^^^^^^^^^^^^^^^^^^^^^^^^^^^^
  File "/usr/local/lib/python3.12/dist-packages/grpc/_channel.py", line 1198, in with_call
    return _end_unary_response_blocking(state, call, True, None)
           ^^^^^^^^^^^^^^^^^^^^^^^^^^^^^^^^^^^^^^^^^^^^^^^^^^^^^
  File "/usr/local/lib/python3.12/dist-packages/grpc/_channel.py", line 1006, in _end_unary_response_blocking
    raise _InactiveRpcError(state)  # pytype: disable=not-instantiable
    ^^^^^^^^^^^^^^^^^^^^^^^^^^^^^^
grpc._channel._InactiveRpcError: <_InactiveRpcError of RPC that terminated with:
	status = StatusCode.UNAVAILABLE
	details = "Getting metadata from plugin failed with error: string indices must be integers, not 'str'"
	debug_error_string = "UNKNOWN:Error received from peer  {grpc_status:14, grpc_message:"Getting metadata from plugin failed with error: string indices must be integers, not \'str\'"}"
>

The above exception was the direct cause of the following exception:

Traceback (most recent call last):
  File "/home/admin_/.local/lib/python3.12/site-packages/starlette/routing.py", line 694, in lifespan
    async with self.lifespan_context(app) as maybe_state:
  File "/home/admin_/.local/lib/python3.12/site-packages/starlette/routing.py", line 571, in __aenter__
    await self._router.startup()
  File "/home/admin_/.local/lib/python3.12/site-packages/starlette/routing.py", line 673, in startup
    handler()
  File "/home/admin_/final_demo/capi/demo-gen-capi/backend/api.py", line 185, in startup_event
    create_data_agent()
  File "/home/admin_/final_demo/capi/demo-gen-capi/backend/api.py", line 83, in create_data_agent
    raise e
  File "/home/admin_/final_demo/capi/demo-gen-capi/backend/api.py", line 77, in create_data_agent
    client.create_data_agent(request=request)
  File "/home/admin_/.local/lib/python3.12/site-packages/google/cloud/geminidataanalytics_v1alpha/services/data_agent_service/client.py", line 1212, in create_data_agent
    response = rpc(
               ^^^^
  File "/usr/local/lib/python3.12/dist-packages/google/api_core/gapic_v1/method.py", line 131, in __call__
    return wrapped_func(*args, **kwargs)
           ^^^^^^^^^^^^^^^^^^^^^^^^^^^^^
  File "/usr/local/lib/python3.12/dist-packages/google/api_core/grpc_helpers.py", line 78, in error_remapped_callable
    raise exceptions.from_grpc_error(exc) from exc
google.api_core.exceptions.ServiceUnavailable: 503 Getting metadata from plugin failed with error: string indices must be integers, not 'str'

ERROR:    Application startup failed. Exiting.
WARNING:  StatReload detected changes in 'api.py'. Reloading...
INFO:     Started server process [15432]
INFO:     Waiting for application startup.
ERROR:    Traceback (most recent call last):
  File "/usr/local/lib/python3.12/dist-packages/google/api_core/grpc_helpers.py", line 76, in error_remapped_callable
    return callable_(*args, **kwargs)
           ^^^^^^^^^^^^^^^^^^^^^^^^^^
  File "/usr/local/lib/python3.12/dist-packages/grpc/_interceptor.py", line 277, in __call__
    response, ignored_call = self._with_call(
                             ^^^^^^^^^^^^^^^^
  File "/usr/local/lib/python3.12/dist-packages/grpc/_interceptor.py", line 332, in _with_call
    return call.result(), call
           ^^^^^^^^^^^^^
  File "/usr/local/lib/python3.12/dist-packages/grpc/_channel.py", line 440, in result
    raise self
  File "/usr/local/lib/python3.12/dist-packages/grpc/_interceptor.py", line 315, in continuation
    response, call = self._thunk(new_method).with_call(
                     ^^^^^^^^^^^^^^^^^^^^^^^^^^^^^^^^^^
  File "/usr/local/lib/python3.12/dist-packages/grpc/_channel.py", line 1198, in with_call
    return _end_unary_response_blocking(state, call, True, None)
           ^^^^^^^^^^^^^^^^^^^^^^^^^^^^^^^^^^^^^^^^^^^^^^^^^^^^^
  File "/usr/local/lib/python3.12/dist-packages/grpc/_channel.py", line 1006, in _end_unary_response_blocking
    raise _InactiveRpcError(state)  # pytype: disable=not-instantiable
    ^^^^^^^^^^^^^^^^^^^^^^^^^^^^^^
grpc._channel._InactiveRpcError: <_InactiveRpcError of RPC that terminated with:
	status = StatusCode.UNAVAILABLE
	details = "Getting metadata from plugin failed with error: string indices must be integers, not 'str'"
	debug_error_string = "UNKNOWN:Error received from peer  {grpc_status:14, grpc_message:"Getting metadata from plugin failed with error: string indices must be integers, not \'str\'"}"
>

The above exception was the direct cause of the following exception:

Traceback (most recent call last):
  File "/home/admin_/.local/lib/python3.12/site-packages/starlette/routing.py", line 694, in lifespan
    async with self.lifespan_context(app) as maybe_state:
  File "/home/admin_/.local/lib/python3.12/site-packages/starlette/routing.py", line 571, in __aenter__
    await self._router.startup()
  File "/home/admin_/.local/lib/python3.12/site-packages/starlette/routing.py", line 673, in startup
    handler()
  File "/home/admin_/final_demo/capi/demo-gen-capi/backend/api.py", line 171, in startup_event
    create_data_agent()
  File "/home/admin_/final_demo/capi/demo-gen-capi/backend/api.py", line 69, in create_data_agent
    raise e
  File "/home/admin_/final_demo/capi/demo-gen-capi/backend/api.py", line 63, in create_data_agent
    client.create_data_agent(request=request)
  File "/home/admin_/.local/lib/python3.12/site-packages/google/cloud/geminidataanalytics_v1alpha/services/data_agent_service/client.py", line 1212, in create_data_agent
    response = rpc(
               ^^^^
  File "/usr/local/lib/python3.12/dist-packages/google/api_core/gapic_v1/method.py", line 131, in __call__
    return wrapped_func(*args, **kwargs)
           ^^^^^^^^^^^^^^^^^^^^^^^^^^^^^
  File "/usr/local/lib/python3.12/dist-packages/google/api_core/grpc_helpers.py", line 78, in error_remapped_callable
    raise exceptions.from_grpc_error(exc) from exc
google.api_core.exceptions.ServiceUnavailable: 503 Getting metadata from plugin failed with error: string indices must be integers, not 'str'

ERROR:    Application startup failed. Exiting.
